Workbook

Sheet Read me
A1: Impact Tracker data template
A3: What this is | B3: Everything the Impact Tracker demo shows, in one workbook. It is pre-filled with a sample Global News Programme (5 focus areas, 8 initiatives). Replace the rows with your own programme, then load the file into the demo.
A4: How to use it | B4: 1. Start with Programme, People, Focus areas and Initiatives. 2. Add Metrics for each initiative, then their Entries (one row per metric per date). 3. Optionally add Campaigns, Campaign results, Evidence, Spend, Responsibilities, Risks, Decisions and Snapshots. 4. In the demo, choose "Load your data" in the dark bar at the top and pick this file. The demo checks every row and tells you about anything it can't use before replacing the data.
A5: Legend | B5: White cells: yours to edit. Grey columns (dark grey header): calculated, don't type in them. Dropdowns: pick a value from the list.
A6: Rules | B6: • Keep the column headers exactly as they are. You can add, delete and reorder rows. • Names link sheets together, so they must match exactly: an Initiative's "Focus area", a Metric's "Initiative", an Entry's "Metric", an Owner's name on People. • Dates as real dates or text in YYYY-MM-DD. • Money as plain numbers, in the programme currency. • Delete a sample row to remove it; leave a sheet with just its header row to have none of that kind.
A7: Sheets | B7: Programme · People · Focus areas · Initiatives · Metrics · Entries · Library · Campaigns · Campaign results · Evidence · Spend · Responsibilities · Risks · Decisions · Snapshots · Summary (calculated)
A8: Choices | B8: Level: input, activity, output, outcome, impact. How entries combine: point (latest value counts) or cumulative (entries are added up). Audience: external, internal, both. Confidence: measured, self-reported, estimated, modelled. Role: admin (Global lead), programme, partner, viewer. Partners need a team: comms, gapp, marketing.
A9: Example row | B9: Metrics sheet: Newsroom Digital Skills Training | Journalists trained | Unique journalists completing at least one full training session | output | people | increase | cumulative | 0 | 300 | (blank) | monthly | Attendance registers | Yes | external | Trainees applying new skills | People trained
A10: Source | B10: Sample figures are illustrative, made up for the demo. They are not real results.

Sheet Programme
A1: Field | B1: Value | C1: Notes
A2: Name | B2: Global News Programme
A3: Mission | B3: Help news organisations and the people who work with them build the skills, audiences and support that keep reliable journalism going. | C3: One or two sentences
A4: Description | B4: A global programme run with Comms, Government Affairs & Public Policy and Marketing, across five focus areas: trainings, product and technology partnerships, research, events, and policy and public affairs.
A5: Currency | B5: USD | C5: USD, GBP or EUR
A6: Budget | B6: 500000 | C6: Total programme budget. Focus area budgets should add up to this.
A7: Start date | B7: 46082 | C7: YYYY-MM-DD
A8: End date | B8: 46446 | C8: YYYY-MM-DD
A9: Demo date | B9: 46288 | C9: The 'today' the demo uses, so example data reads as current. Change it to your presentation date if your data is current.

Sheet People
A1: Name | B1: Email | C1: Role | D1: Partner team
A2: Nadia Hassan | B2: lead@example.org | C2: admin
A3: Tom Reeves | B3: programme@example.org | C3: programme
A4: Priya Shah | B4: comms@example.org | C4: partner | D4: comms
A5: Daniel Mensah | B5: gapp@example.org | C5: partner | D5: gapp
A6: Sofia Lindqvist | B6: marketing@example.org | C6: partner | D6: marketing

Sheet Focus areas
A1: Name | B1: Description | C1: Owner | D1: Budget
A2: Trainings | B2: Skills training for journalists and newsrooms (external), and news-literacy training that turns colleagues into programme champions (internal). | C2: Nadia Hassan | D2: 230000
A3: Product & Technology Partnerships | B3: Free and discounted newsroom tools from product partners, and a feedback loop so product teams build what newsrooms need. | C3: Tom Reeves | D3: 110000
A4: Research & Insights | B4: Evidence on local news audiences and business models, for newsrooms, policymakers and internal teams. | C4: Tom Reeves | D4: 60000
A5: Events & Convenings | B5: The flagship summit for newsroom leaders, and internal events that keep colleagues close to the programme. | C5: Nadia Hassan | D5: 70000
A6: Policy & Public Affairs | B6: Working with Government Affairs & Public Policy so programme evidence informs policy on local news. | C6: Daniel Mensah | D6: 30000

Sheet Initiatives
A1: Name | B1: Focus area | C1: Description | D1: Owner | E1: Start date | F1: End date | G1: Budget | H1: Region | I1: Status | J1: ToC: inputs | K1: ToC: activities | L1: ToC: outputs | M1: ToC: outcomes | N1: ToC: impact
A2: Newsroom Digital Skills Training | B2: Trainings | C2: Training cohorts, a shared digital toolkit and small grants that help independent local newsrooms build digital audiences and sustainable revenue. | D2: Nadia Hassan | E2: 46082 | F2: 46446 | G2: 190000 | H2: UK & Ireland | I2: active | J2: $190k budget including a grant fund; 3 programme staff; trainer network of 12 working journalists; shared analytics and CMS toolkit. | K2: Monthly training cohorts on audience development and revenue; toolkit onboarding and support; small grants for pilots; peer-learning roadshow. | L2: 300 journalists trained; 40 newsrooms onboarded to the toolkit; 30 newsrooms using audience analytics every week. | M2: Newsrooms grow digital audiences, add new revenue streams, and staff apply new skills; local readers trust their local news more. | N2: More local news organisations are financially sustainable, so communities keep access to reliable local reporting.
A3: Newsroom Champions (internal) | B3: Trainings | C3: News-literacy sessions for colleagues, and a champions network who explain the programme and use its stories in their own teams. | D3: Tom Reeves | E3: 46082 | F3: 46446 | G3: 40000 | H3: Global | I3: active | J3: $40k; 1 programme lead; content from the external training; support from Comms and Marketing. | K3: Monthly news-literacy sessions; a champions certification; an internal case-study pack. | L3: 400 colleagues trained; 40 certified champions. | M3: Colleagues can explain the programme confidently and use its stories with partners and policymakers. | N3: The organisation speaks about news and journalism with one informed voice.
A4: Newsroom Tools Partnership | B4: Product & Technology Partnerships | C4: Onboards newsrooms to partner publishing, transcription and analytics tools, with training and support. | D4: Tom Reeves | E4: 46082 | F4: 46446 | G4: 80000 | H4: Global | I4: active | J4: $80k; partner tools at no cost to newsrooms; 1 partnerships manager; support desk. | K4: Newsroom onboarding; monthly tool clinics; integration support. | L4: 60 partner newsrooms live; 6,000 stories published with the tools. | M4: Journalists save time on routine tasks and use the tools every week. | N4: Newsrooms spend more time on original reporting.
A5: Product Feedback Loop (internal) | B5: Product & Technology Partnerships | C5: Brings newsroom feedback to internal product teams, so tools are built around real newsroom needs. | D5: Tom Reeves | E5: 46082 | F5: 46446 | G5: 30000 | H5: Global | I5: active | J5: $30k; programme staff time; access to product teams. | K5: Monthly feedback sessions; a shared insights log; newsroom visits for product staff. | L5: 24 feedback sessions held. | M5: Product teams use newsroom insights in planning and ship requested features. | N5: The organisation's products serve news organisations better.
A6: Local News Audience Study | B6: Research & Insights | C6: A large survey of local news audiences, published as short briefs and a full report. | D6: Tom Reeves | E6: 46082 | F6: 46446 | G6: 60000 | H6: Global | I6: active | J6: $60k; survey panel; 1 researcher; academic adviser. | K6: Fieldwork in 6 countries; analysis; briefs and report. | L6: 5,000 survey responses; 6 research briefs. | M6: Findings are cited by policymakers and press, and used by internal teams. | N6: Decisions about local news are based on evidence.
A7: Global News Summit 2026 | B7: Events & Convenings | C7: Two-day summit in November for newsroom leaders, partners and policymakers. | D7: Nadia Hassan | E7: 46082 | F7: 46446 | G7: 55000 | H7: Global (in person and online) | I7: active | J7: $55k; venue partner; sponsors; programme and Marketing staff. | K7: Programme design; speaker and sponsor outreach; registration campaign. | L7: 800 registrations; 40 speakers. | M7: Attendees rate it highly and start partnerships afterwards. | N7: A stronger network of organisations supporting local news.
A8: Lunch & Learn series (internal) | B8: Events & Convenings | C8: Monthly internal sessions where newsroom partners and programme staff share stories and results with colleagues. | D8: Priya Shah | E8: 46082 | F8: 46446 | G8: 15000 | H8: Global | I8: active | J8: $15k; Comms support; guest speakers from partner newsrooms. | K8: Monthly lunch-and-learn sessions, in person and online. | L8: 20 sessions; 1,200 colleague attendances. | M8: Colleagues understand the programme and share its stories. | N8: Stronger internal support for the programme.
A9: Policy Engagement on Local News | B9: Policy & Public Affairs | C9: Briefings, consultation responses and roundtables that bring programme evidence to policymakers. | D9: Daniel Mensah | E9: 46082 | F9: 46446 | G9: 30000 | H9: UK, EU and US | I9: active | J9: $30k; GAPP team time; programme data and case studies. | K9: Policymaker briefings; written submissions; roundtables with newsrooms. | L9: 24 briefings; 6 submissions; 60 policymakers engaged. | M9: Programme evidence is cited in policy and officials ask for more. | N9: Policy that supports a sustainable local news sector.

Sheet Metrics
A1: Initiative | B1: Metric | C1: Definition | D1: Level | E1: Unit | F1: Good direction | G1: How entries combine | H1: Baseline | I1: Target | J1: Target date | K1: Frequency | L1: Data source | M1: Key metric | N1: Audience | O1: Leading indicator for | P1: Library definition | Q1: Focus area (calculated)
A2: Newsroom Digital Skills Training | B2: Training grants disbursed | C2: Grant payments released to participating newsrooms to cover training time and pilots. | D2: input | E2: $ | F2: increase | G2: cumulative | H2: 0 | I2: 120000 | K2: monthly | L2: Finance system | M2: No | N2: external | Q2: =IFERROR(INDEX(Initiatives!$B$2:$B$500,MATCH(A2,Initiatives!$A$2:$A$500,0)),"")
A3: Newsroom Digital Skills Training | B3: Training sessions delivered | C3: Live training sessions (online or in person) of at least 90 minutes. | D3: activity | E3: sessions | F3: increase | G3: cumulative | H3: 0 | I3: 48 | K3: monthly | L3: Training calendar | M3: No | N3: external | Q3: =IFERROR(INDEX(Initiatives!$B$2:$B$500,MATCH(A3,Initiatives!$A$2:$A$500,0)),"")
A4: Newsroom Digital Skills Training | B4: Newsrooms onboarded to digital toolkit | C4: Newsrooms with an active toolkit account and a completed onboarding call. | D4: activity | E4: newsrooms | F4: increase | G4: cumulative | H4: 0 | I4: 40 | K4: monthly | L4: Toolkit CRM | M4: No | N4: external | P4: Organisations onboarded | Q4: =IFERROR(INDEX(Initiatives!$B$2:$B$500,MATCH(A4,Initiatives!$A$2:$A$500,0)),"")
A5: Newsroom Digital Skills Training | B5: Journalists trained | C5: Unique journalists completing at least one full training session. | D5: output | E5: people | F5: increase | G5: cumulative | H5: 0 | I5: 300 | K5: monthly | L5: Attendance registers | M5: Yes | N5: external | O5: Trainees applying new skills | P5: People trained | Q5: =IFERROR(INDEX(Initiatives!$B$2:$B$500,MATCH(A5,Initiatives!$A$2:$A$500,0)),"")
A6: Newsroom Digital Skills Training | B6: Newsrooms using analytics weekly | C6: Newsrooms that logged into the analytics dashboard in at least 3 of the last 4 weeks. | D6: output | E6: newsrooms | F6: increase | G6: point | H6: 0 | I6: 30 | K6: monthly | L6: Toolkit usage logs | M6: No | N6: external | O6: Average monthly digital audience per newsroom | Q6: =IFERROR(INDEX(Initiatives!$B$2:$B$500,MATCH(A6,Initiatives!$A$2:$A$500,0)),"")
A7: Newsroom Digital Skills Training | B7: Average monthly digital audience per newsroom | C7: Median monthly unique visitors across participating newsrooms' websites. | D7: outcome | E7: unique visitors | F7: increase | G7: point | H7: 12000 | I7: 18000 | K7: monthly | L7: Web analytics (shared toolkit) | M7: Yes | N7: external | Q7: =IFERROR(INDEX(Initiatives!$B$2:$B$500,MATCH(A7,Initiatives!$A$2:$A$500,0)),"")
A8: Newsroom Digital Skills Training | B8: Newsrooms with a new revenue stream | C8: Share of participating newsrooms that launched a revenue stream (memberships, events, sponsorship) since joining. | D8: outcome | E8: % | F8: increase | G8: point | H8: 15 | I8: 50 | K8: monthly | L8: Monthly check-in form | M8: No | N8: external | O8: Financially sustainable newsrooms | Q8: =IFERROR(INDEX(Initiatives!$B$2:$B$500,MATCH(A8,Initiatives!$A$2:$A$500,0)),"")
A9: Newsroom Digital Skills Training | B9: Trainees applying new skills | C9: Share of trainees who report using a technique from training in the last month, surveyed 8+ weeks after training. | D9: outcome | E9: % | F9: increase | G9: point | H9: 0 | I9: 70 | K9: quarterly | L9: Follow-up survey | M9: No | N9: external | P9: Trainees applying new skills | Q9: =IFERROR(INDEX(Initiatives!$B$2:$B$500,MATCH(A9,Initiatives!$A$2:$A$500,0)),"")
A10: Newsroom Digital Skills Training | B10: Reader trust score | C10: Mean answer to 'How much do you trust this outlet?' on a 1-10 scale, across participating newsrooms' reader surveys. | D10: outcome | E10: score (1-10) | F10: increase | G10: point | H10: 6.2 | I10: 7 | K10: quarterly | L10: Reader survey | M10: No | N10: external | P10: Audience trust score | Q10: =IFERROR(INDEX(Initiatives!$B$2:$B$500,MATCH(A10,Initiatives!$A$2:$A$500,0)),"")
A11: Newsroom Digital Skills Training | B11: Financially sustainable newsrooms | C11: Participating newsrooms whose revenue covers operating costs for 3 consecutive months. | D11: impact | E11: newsrooms | F11: increase | G11: point | H11: 8 | I11: 20 | K11: quarterly | L11: Financial returns (modelled from partial data) | M11: Yes | N11: external | Q11: =IFERROR(INDEX(Initiatives!$B$2:$B$500,MATCH(A11,Initiatives!$A$2:$A$500,0)),"")
A12: Newsroom Champions (internal) | B12: Colleagues completing news-literacy training | D12: output | E12: people | F12: increase | G12: cumulative | H12: 0 | I12: 400 | K12: monthly | L12: Learning platform | M12: Yes | N12: internal | Q12: =IFERROR(INDEX(Initiatives!$B$2:$B$500,MATCH(A12,Initiatives!$A$2:$A$500,0)),"")
A13: Newsroom Champions (internal) | B13: Certified internal champions | D13: output | E13: champions | F13: increase | G13: cumulative | H13: 0 | I13: 40 | K13: monthly | L13: Champions register | M13: No | N13: internal | O13: Colleagues confident explaining the programme | Q13: =IFERROR(INDEX(Initiatives!$B$2:$B$500,MATCH(A13,Initiatives!$A$2:$A$500,0)),"")
A14: Newsroom Champions (internal) | B14: Colleagues confident explaining the programme | D14: outcome | E14: % | F14: increase | G14: point | H14: 35 | I14: 70 | K14: quarterly | L14: Quarterly pulse survey | M14: Yes | N14: internal | Q14: =IFERROR(INDEX(Initiatives!$B$2:$B$500,MATCH(A14,Initiatives!$A$2:$A$500,0)),"")
A15: Newsroom Champions (internal) | B15: Teams using programme case studies | D15: outcome | E15: teams | F15: increase | G15: point | H15: 0 | I15: 15 | K15: monthly | L15: Comms request log | M15: No | N15: internal | Q15: =IFERROR(INDEX(Initiatives!$B$2:$B$500,MATCH(A15,Initiatives!$A$2:$A$500,0)),"")
A16: Newsroom Tools Partnership | B16: Partner newsrooms live on the tools | C16: Newsrooms with at least one partner tool in weekly use. | D16: output | E16: newsrooms | F16: increase | G16: point | H16: 0 | I16: 60 | K16: monthly | L16: Partner dashboards | M16: Yes | N16: external | Q16: =IFERROR(INDEX(Initiatives!$B$2:$B$500,MATCH(A16,Initiatives!$A$2:$A$500,0)),"")
A17: Newsroom Tools Partnership | B17: Weekly active journalists on the tools | C17: Unique journalists using a partner tool in the last 7 days. | D17: outcome | E17: journalists | F17: increase | G17: point | H17: 0 | I17: 900 | K17: monthly | L17: Partner analytics | M17: No | N17: external | O17: Partner satisfaction (NPS) | Q17: =IFERROR(INDEX(Initiatives!$B$2:$B$500,MATCH(A17,Initiatives!$A$2:$A$500,0)),"")
A18: Newsroom Tools Partnership | B18: Minutes saved per story | C18: Average time saved on transcription and publishing per story, from the quarterly user survey. | D18: outcome | E18: minutes | F18: increase | G18: point | H18: 0 | I18: 20 | K18: quarterly | L18: User survey | M18: No | N18: external | Q18: =IFERROR(INDEX(Initiatives!$B$2:$B$500,MATCH(A18,Initiatives!$A$2:$A$500,0)),"")
A19: Newsroom Tools Partnership | B19: Stories published with partner tools | C19: Stories published through partner publishing tools. | D19: output | E19: stories | F19: increase | G19: cumulative | H19: 0 | I19: 6000 | K19: monthly | L19: Partner analytics | M19: No | N19: external | Q19: =IFERROR(INDEX(Initiatives!$B$2:$B$500,MATCH(A19,Initiatives!$A$2:$A$500,0)),"")
A20: Newsroom Tools Partnership | B20: Partner satisfaction (NPS) | C20: Net Promoter Score from newsroom users of partner tools. | D20: outcome | E20: NPS | F20: increase | G20: point | H20: 20 | I20: 50 | K20: quarterly | L20: User survey | M20: Yes | N20: external | Q20: =IFERROR(INDEX(Initiatives!$B$2:$B$500,MATCH(A20,Initiatives!$A$2:$A$500,0)),"")
A21: Product Feedback Loop (internal) | B21: Newsroom feedback sessions with product teams | C21: Structured sessions where newsroom users meet product teams. | D21: activity | E21: sessions | F21: increase | G21: cumulative | H21: 0 | I21: 24 | K21: monthly | L21: Programme log | M21: No | N21: internal | Q21: =IFERROR(INDEX(Initiatives!$B$2:$B$500,MATCH(A21,Initiatives!$A$2:$A$500,0)),"")
A22: Product Feedback Loop (internal) | B22: Product teams using newsroom insights | C22: Product teams that cite programme insights in their quarterly plans. | D22: outcome | E22: teams | F22: increase | G22: point | H22: 0 | I22: 12 | K22: monthly | L22: Product planning docs | M22: Yes | N22: internal | Q22: =IFERROR(INDEX(Initiatives!$B$2:$B$500,MATCH(A22,Initiatives!$A$2:$A$500,0)),"")
A23: Product Feedback Loop (internal) | B23: Newsroom-requested features shipped | C23: Features shipped that trace back to a newsroom request in the insights log. | D23: output | E23: features | F23: increase | G23: cumulative | H23: 0 | I23: 10 | K23: monthly | L23: Insights log | M23: No | N23: internal | Q23: =IFERROR(INDEX(Initiatives!$B$2:$B$500,MATCH(A23,Initiatives!$A$2:$A$500,0)),"")
A24: Local News Audience Study | B24: Survey responses collected | C24: Completed responses meeting quality checks. | D24: activity | E24: responses | F24: increase | G24: cumulative | H24: 0 | I24: 5000 | K24: monthly | L24: Survey panel | M24: No | N24: both | Q24: =IFERROR(INDEX(Initiatives!$B$2:$B$500,MATCH(A24,Initiatives!$A$2:$A$500,0)),"")
A25: Local News Audience Study | B25: Research briefs published | C25: Short briefs published on the programme website. | D25: output | E25: briefs | F25: increase | G25: cumulative | H25: 0 | I25: 6 | K25: monthly | L25: Website | M25: No | N25: both | Q25: =IFERROR(INDEX(Initiatives!$B$2:$B$500,MATCH(A25,Initiatives!$A$2:$A$500,0)),"")
A26: Local News Audience Study | B26: Report downloads | C26: Downloads of briefs and the full report. | D26: output | E26: downloads | F26: increase | G26: cumulative | H26: 0 | I26: 4000 | K26: monthly | L26: Website analytics | M26: No | N26: external | O26: Citations in policy papers and press | Q26: =IFERROR(INDEX(Initiatives!$B$2:$B$500,MATCH(A26,Initiatives!$A$2:$A$500,0)),"")
A27: Local News Audience Study | B27: Citations in policy papers and press | C27: Policy documents and press articles citing the study. | D27: outcome | E27: citations | F27: increase | G27: cumulative | H27: 0 | I27: 25 | K27: monthly | L27: Media and policy monitoring | M27: Yes | N27: external | Q27: =IFERROR(INDEX(Initiatives!$B$2:$B$500,MATCH(A27,Initiatives!$A$2:$A$500,0)),"")
A28: Local News Audience Study | B28: Internal teams using the findings | C28: Internal teams that used a finding in a plan, pitch or briefing. | D28: outcome | E28: teams | F28: increase | G28: point | H28: 0 | I28: 10 | K28: monthly | L28: Internal survey | M28: Yes | N28: internal | Q28: =IFERROR(INDEX(Initiatives!$B$2:$B$500,MATCH(A28,Initiatives!$A$2:$A$500,0)),"")
A29: Global News Summit 2026 | B29: Summit registrations | C29: Confirmed registrations (in person and online). | D29: output | E29: registrations | F29: increase | G29: cumulative | H29: 0 | I29: 800 | K29: monthly | L29: Registration platform | M29: Yes | N29: external | Q29: =IFERROR(INDEX(Initiatives!$B$2:$B$500,MATCH(A29,Initiatives!$A$2:$A$500,0)),"")
A30: Global News Summit 2026 | B30: Speakers confirmed | C30: Speakers with signed confirmations. | D30: activity | E30: speakers | F30: increase | G30: cumulative | H30: 0 | I30: 40 | K30: monthly | L30: Programme plan | M30: No | N30: external | Q30: =IFERROR(INDEX(Initiatives!$B$2:$B$500,MATCH(A30,Initiatives!$A$2:$A$500,0)),"")
A31: Global News Summit 2026 | B31: Sponsor and partner commitments | C31: Signed sponsorship or in-kind partner agreements. | D31: input | E31: sponsors | F31: increase | G31: cumulative | H31: 0 | I31: 12 | K31: monthly | L31: Partnership agreements | M31: No | N31: external | Q31: =IFERROR(INDEX(Initiatives!$B$2:$B$500,MATCH(A31,Initiatives!$A$2:$A$500,0)),"")
A32: Global News Summit 2026 | B32: Partnerships started after events | C32: Collaborations between attendees reported in follow-up surveys (from this year's roadshow and meet-ups). | D32: outcome | E32: partnerships | F32: increase | G32: cumulative | H32: 0 | I32: 30 | K32: monthly | L32: Follow-up survey | M32: Yes | N32: external | Q32: =IFERROR(INDEX(Initiatives!$B$2:$B$500,MATCH(A32,Initiatives!$A$2:$A$500,0)),"")
A33: Global News Summit 2026 | B33: Attendee satisfaction | C33: Average rating of programme events this year. | D33: outcome | E33: score (1-10) | F33: increase | G33: point | H33: 7.5 | I33: 8.5 | K33: quarterly | L33: Event feedback forms | M33: No | N33: external | Q33: =IFERROR(INDEX(Initiatives!$B$2:$B$500,MATCH(A33,Initiatives!$A$2:$A$500,0)),"")
A34: Lunch & Learn series (internal) | B34: Sessions held | C34: Lunch & Learn sessions delivered. | D34: activity | E34: sessions | F34: increase | G34: cumulative | H34: 0 | I34: 20 | K34: monthly | L34: Events calendar | M34: No | N34: internal | Q34: =IFERROR(INDEX(Initiatives!$B$2:$B$500,MATCH(A34,Initiatives!$A$2:$A$500,0)),"")
A35: Lunch & Learn series (internal) | B35: Colleague attendances | C35: Total attendances, in person and online. | D35: output | E35: attendances | F35: increase | G35: cumulative | H35: 0 | I35: 1200 | K35: monthly | L35: Registration list | M35: Yes | N35: internal | Q35: =IFERROR(INDEX(Initiatives!$B$2:$B$500,MATCH(A35,Initiatives!$A$2:$A$500,0)),"")
A36: Lunch & Learn series (internal) | B36: Attendees who understand the programme better | C36: Share of attendees agreeing they understand the programme better after a session. | D36: outcome | E36: % | F36: increase | G36: point | H36: 0 | I36: 80 | K36: quarterly | L36: Session feedback | M36: No | N36: internal | Q36: =IFERROR(INDEX(Initiatives!$B$2:$B$500,MATCH(A36,Initiatives!$A$2:$A$500,0)),"")
A37: Policy Engagement on Local News | B37: Policymaker briefings held | C37: Meetings or calls with officials where programme evidence was presented. | D37: activity | E37: briefings | F37: increase | G37: cumulative | H37: 0 | I37: 24 | K37: monthly | L37: GAPP contact log | M37: No | N37: external | Q37: =IFERROR(INDEX(Initiatives!$B$2:$B$500,MATCH(A37,Initiatives!$A$2:$A$500,0)),"")
A38: Policy Engagement on Local News | B38: Written submissions to consultations | C38: Formal responses to government or regulator consultations. | D38: output | E38: submissions | F38: increase | G38: cumulative | H38: 0 | I38: 6 | K38: monthly | L38: GAPP tracker | M38: No | N38: external | O38: Programme evidence cited in policy documents | Q38: =IFERROR(INDEX(Initiatives!$B$2:$B$500,MATCH(A38,Initiatives!$A$2:$A$500,0)),"")
A39: Policy Engagement on Local News | B39: Policymakers engaged | C39: Unique officials and elected representatives engaged. | D39: output | E39: people | F39: increase | G39: cumulative | H39: 0 | I39: 60 | K39: monthly | L39: GAPP contact log | M39: Yes | N39: external | Q39: =IFERROR(INDEX(Initiatives!$B$2:$B$500,MATCH(A39,Initiatives!$A$2:$A$500,0)),"")
A40: Policy Engagement on Local News | B40: Programme evidence cited in policy documents | C40: Policy documents, speeches or reports citing programme data or case studies. | D40: outcome | E40: citations | F40: increase | G40: cumulative | H40: 0 | I40: 10 | K40: monthly | L40: Policy monitoring | M40: Yes | N40: external | Q40: =IFERROR(INDEX(Initiatives!$B$2:$B$500,MATCH(A40,Initiatives!$A$2:$A$500,0)),"")
...

Sheet Entries
A1: Initiative | B1: Metric | C1: Date | D1: Value | E1: Confidence | F1: Note | G1: Logged by
A2: Newsroom Digital Skills Training | B2: Training grants disbursed | C2: 46113 | D2: 8000 | E2: measured | G2: Nadia Hassan
A3: Newsroom Digital Skills Training | B3: Training grants disbursed | C3: 46143 | D3: 6800 | E3: measured | G3: Tom Reeves
A4: Newsroom Digital Skills Training | B4: Training grants disbursed | C4: 46174 | D4: 9200 | E4: measured | G4: Nadia Hassan
A5: Newsroom Digital Skills Training | B5: Training grants disbursed | C5: 46204 | D5: 8000 | E5: measured | G5: Tom Reeves
A6: Newsroom Digital Skills Training | B6: Training grants disbursed | C6: 46235 | D6: 6800 | E6: measured | G6: Nadia Hassan
A7: Newsroom Digital Skills Training | B7: Training grants disbursed | C7: 46266 | D7: 9200 | E7: measured | G7: Tom Reeves
A8: Newsroom Digital Skills Training | B8: Training sessions delivered | C8: 46113 | D8: 4 | E8: measured | G8: Nadia Hassan
A9: Newsroom Digital Skills Training | B9: Training sessions delivered | C9: 46143 | D9: 4 | E9: measured | G9: Tom Reeves
A10: Newsroom Digital Skills Training | B10: Training sessions delivered | C10: 46174 | D10: 5 | E10: measured | G10: Nadia Hassan
A11: Newsroom Digital Skills Training | B11: Training sessions delivered | C11: 46204 | D11: 5 | E11: measured | G11: Tom Reeves
A12: Newsroom Digital Skills Training | B12: Training sessions delivered | C12: 46235 | D12: 4 | E12: measured | G12: Nadia Hassan
A13: Newsroom Digital Skills Training | B13: Training sessions delivered | C13: 46266 | D13: 5 | E13: measured | G13: Tom Reeves
... A33: Newsroom Digital Skills Training | B33: Average monthly digital audience per newsroom | C33: 46143 | D33: 12400 | E33: estimated | G33: Tom Reeves
A34: Newsroom Digital Skills Training | B34: Average monthly digital audience per newsroom | C34: 46174 | D34: 12900 | E34: estimated | F34: Jump partly from the YouTube series driving traffic to partner sites. | G34: Nadia Hassan
A35: Newsroom Digital Skills Training | B35: Average monthly digital audience per newsroom | C35: 46204 | D35: 13100 | E35: estimated | G35: Tom Reeves
A36: Newsroom Digital Skills Training | B36: Average monthly digital audience per newsroom | C36: 46235 | D36: 13300 | E36: estimated | G36: Nadia Hassan
A37: Newsroom Digital Skills Training | B37: Average monthly digital audience per newsroom | C37: 46266 | D37: 13500 | E37: estimated | G37: Tom Reeves
A38: Newsroom Digital Skills Training | B38: Newsrooms with a new revenue stream | C38: 46113 | D38: 15 | E38: self-reported | G38: Nadia Hassan
A39: Newsroom Digital Skills Training | B39: Newsrooms with a new revenue stream | C39: 46143 | D39: 18 | E39: self-reported | G39: Tom Reeves
A40: Newsroom Digital Skills Training | B40: Newsrooms with a new revenue stream | C40: 46174 | D40: 22 | E40: self-reported | G40: Nadia Hassan
A41: Newsroom Digital Skills Training | B41: Newsrooms with a new revenue stream | C41: 46204 | D41: 26 | E41: self-reported | G41: Tom Reeves
A42: Newsroom Digital Skills Training | B42: Newsrooms with a new revenue stream | C42: 46235 | D42: 30 | E42: self-reported | G42: Nadia Hassan
A43: Newsroom Digital Skills Training | B43: Newsrooms with a new revenue stream | C43: 46266 | D43: 33 | E43: self-reported | G43: Tom Reeves
A44: Newsroom Digital Skills Training | B44: Trainees applying new skills | C44: 46174 | D44: 58 | E44: self-reported | G44: Nadia Hassan
A45: Newsroom Digital Skills Training | B45: Trainees applying new skills | C45: 46266 | D45: 64 | E45: self-reported | G45: Tom Reeves
A46: Newsroom Digital Skills Training | B46: Reader trust score | C46: 46174 | D46: 6.4 | E46: self-reported | G46: Nadia Hassan
... A49: Newsroom Digital Skills Training | B49: Financially sustainable newsrooms | C49: 46204 | D49: 10 | E49: modelled | G49: Tom Reeves
A50: Newsroom Digital Skills Training | B50: Financially sustainable newsrooms | C50: 46266 | D50: 11 | E50: modelled | F50: Modelled from 14 of 22 newsrooms' returns; remainder due in October. | G50: Tom Reeves
A51: Newsroom Champions (internal) | B51: Colleagues completing news-literacy training | C51: 46113 | D51: 30 | E51: measured | G51: Tom Reeves
A52: Newsroom Champions (internal) | B52: Colleagues completing news-literacy training | C52: 46143 | D52: 45 | E52: measured | G52: Tom Reeves
A53: Newsroom Champions (internal) | B53: Colleagues completing news-literacy training | C53: 46174 | D53: 40 | E53: measured | G53: Tom Reeves
A54: Newsroom Champions (internal) | B54: Colleagues completing news-literacy training | C54: 46204 | D54: 25 | E54: measured | G54: Tom Reeves
A55: Newsroom Champions (internal) | B55: Colleagues completing news-literacy training | C55: 46235 | D55: 20 | E55: measured | G55: Tom Reeves
A56: Newsroom Champions (internal) | B56: Colleagues completing news-literacy training | C56: 46266 | D56: 35 | E56: measured | G56: Tom Reeves
A57: Newsroom Champions (internal) | B57: Certified internal champions | C57: 46113 | D57: 0 | E57: measured | G57: Tom Reeves
A58: Newsroom Champions (internal) | B58: Certified internal champions | C58: 46143 | D58: 4 | E58: measured | G58: Tom Reeves
A59: Newsroom Champions (internal) | B59: Certified internal champions | C59: 46174 | D59: 3 | E59: measured | G59: Tom Reeves
A60: Newsroom Champions (internal) | B60: Certified internal champions | C60: 46204 | D60: 2 | E60: measured | G60: Tom Reeves
A61: Newsroom Champions (internal) | B61: Certified internal champions | C61: 46235 | D61: 1 | E61: measured | G61: Tom Reeves
...

Sheet Library
A1: Name | B1: Definition | C1: Level | D1: Unit | E1: Good direction | F1: How entries combine | G1: Frequency | H1: Data source
A2: Audience trust score | B2: Mean answer to 'How much do you trust this outlet?' on a 1-10 scale. | C2: outcome | D2: score (1-10) | E2: increase | F2: point | G2: quarterly | H2: Reader survey
A3: Organisations onboarded | B3: Organisations with an active account and a completed onboarding call. | C3: activity | D3: organisations | E3: increase | F3: cumulative | G3: monthly | H3: CRM
A4: People trained | B4: Unique people completing at least one full training session. | C4: output | D4: people | E4: increase | F4: cumulative | G4: monthly | H4: Attendance registers
A5: Trainees applying new skills | B5: Share of trainees who report using a technique from training in the last month, surveyed 8+ weeks after training. | C5: outcome | D5: % | E5: increase | F5: point | G5: quarterly | H5: Follow-up survey

Sheet Campaigns
A1: Initiative | B1: Campaign | C1: Channel | D1: Audience | E1: Start date | F1: End date | G1: Spend | H1: Tracking tag | I1: Notes
A2: Newsroom Digital Skills Training | B2: Local News Matters (YouTube series) | C2: youtube | D2: external | E2: 46127 | F2: 46203 | G2: 6000 | H2: utm_campaign=lnm_youtube_2026 | I2: Six short documentaries on local newsrooms, each linking to the featured outlet.
A3: Newsroom Digital Skills Training | B3: Toolkit launch email series | C3: email | D3: external | E3: 46143 | F3: 46173 | G3: 800 | H3: utm_campaign=toolkit_launch | I3: Four-email sequence to 2,300 local editors and publishers.
A4: Newsroom Digital Skills Training | B4: Newsroom Futures roadshow | C4: events | D4: external | E4: 46204 | F4: 46265 | G4: 9000 | H4: EVT-NF26 | I4: Five regional half-day events with peer case studies and toolkit demos.
A5: Newsroom Champions (internal) | B5: Internal launch: town hall and newsletter | C5: events | D5: internal | E5: 46132 | F5: 46157 | G5: 2100 | H5: INT-LAUNCH-26 | I5: Global town hall with the Comms team, followed by a four-part internal newsletter.
A6: Newsroom Tools Partnership | B6: Tools launch webinar series | C6: events | D6: external | E6: 46174 | F6: 46234 | G6: 3000 | H6: WEB-TOOLS-26 | I6: Four webinars demonstrating partner tools to newsroom leaders.
A7: Global News Summit 2026 | B7: Summit early-bird campaign | C7: social | D7: external | E7: 46204 | F7: 46295 | G7: 4000 | H7: utm_campaign=summit26_earlybird | I7: Social ads and partner newsletters promoting early-bird registration.

Sheet Campaign results
A1: Initiative | B1: Campaign | C1: Date | D1: Metric | E1: Value
A2: Newsroom Digital Skills Training | B2: Local News Matters (YouTube series) | C2: 46113 | D2: clicks | E2: 1400
A3: Newsroom Digital Skills Training | B3: Local News Matters (YouTube series) | C3: 46113 | D3: impressions | E3: 85000
A4: Newsroom Digital Skills Training | B4: Local News Matters (YouTube series) | C4: 46113 | D4: sign-ups | E4: 90
A5: Newsroom Digital Skills Training | B5: Local News Matters (YouTube series) | C5: 46113 | D5: views | E5: 21000
A6: Newsroom Digital Skills Training | B6: Local News Matters (YouTube series) | C6: 46143 | D6: clicks | E6: 3100
A7: Newsroom Digital Skills Training | B7: Local News Matters (YouTube series) | C7: 46143 | D7: impressions | E7: 160000
A8: Newsroom Digital Skills Training | B8: Local News Matters (YouTube series) | C8: 46143 | D8: sign-ups | E8: 240
A9: Newsroom Digital Skills Training | B9: Local News Matters (YouTube series) | C9: 46143 | D9: views | E9: 46000
A10: Newsroom Digital Skills Training | B10: Local News Matters (YouTube series) | C10: 46174 | D10: clicks | E10: 2700
A11: Newsroom Digital Skills Training | B11: Local News Matters (YouTube series) | C11: 46174 | D11: impressions | E11: 140000
A12: Newsroom Digital Skills Training | B12: Local News Matters (YouTube series) | C12: 46174 | D12: sign-ups | E12: 210
A13: Newsroom Digital Skills Training | B13: Local News Matters (YouTube series) | C13: 46174 | D13: views | E13: 39000
... A37: Global News Summit 2026 | B37: Summit early-bird campaign | C37: 46266 | D37: sign-ups | E37: 45

Sheet Evidence
A1: Initiative | B1: Metric | C1: Type | D1: Title | E1: Text | F1: Source | G1: Link | H1: Date | I1: Tags | J1: Origin
A2: Newsroom Digital Skills Training | B2: Financially sustainable newsrooms | C2: quote | D2: Publisher on sustainability | E2: We're closer, but one big advertiser leaving would still put us back in the red. The grant bought us time to diversify. | F2: Publisher, Morecambe Bay News | H2: 46280 | I2: sustainability,risk | J2: human
A3: Newsroom Digital Skills Training | B3: Newsrooms with a new revenue stream | C3: survey | D3: Theme: memberships are the most common new revenue stream | E3: Across 38 check-in responses, memberships (14) and local events (9) were the most-cited new revenue streams. Sentiment is mostly positive, with concern about sustaining member numbers after launch. | F3: AI theme coding of monthly check-in forms | H3: 46277 | I3: revenue,theme | J3: ai
A4: Newsroom Digital Skills Training | B4: Trainees applying new skills | C4: survey | D4: Follow-up survey, cohort 1-3 (n=112) | E4: 64% say they used a technique from training in the last month. Most cited: headline testing (41%), newsletter segmentation (29%), audience surveys (18%). | F4: Follow-up survey, September | H4: 46275 | I4: skills,survey | J4: human
A5: Newsroom Digital Skills Training | B5: Reader trust score | C5: quote | D5: Reader survey comment | E5: They actually come to the meetings now and explain what the decisions mean for us. That's why I read them. | F5: Reader, Hebden Bridge | H5: 46267 | I5: trust,readers | J5: human
A6: Newsroom Digital Skills Training | B6: Newsrooms with a new revenue stream | C6: case-study | D6: Tyneside Tribune launches a membership scheme | E6: After the revenue cohort, the Tribune launched a $5/month membership with a members-only newsletter. 310 members joined in the first six weeks, covering one part-time reporter. | F6: Programme case study | H6: 46239 | I6: revenue,membership | J6: human
A7: Newsroom Digital Skills Training | C7: link | D7: Regional press coverage of the roadshow | E7: Article on the Newsroom Futures roadshow and the programme's aims. | F7: Regional business press | G7: https://example.org/press/newsroom-futures | H7: 46225 | I7: press | J7: human
A8: Newsroom Digital Skills Training | B8: Trainees applying new skills | C8: quote | D8: Trainee on newsletter skills | E8: I rebuilt our newsletter the week after the session. Open rates went from 22% to 38%. | F8: Reporter, Wharfedale Weekly | H8: 46203 | I8: skills,newsletter | J8: human
A9: Newsroom Digital Skills Training | B9: Average monthly digital audience per newsroom | C9: quote | D9: Editor on the analytics dashboard | E9: For the first time we can see which stories people actually finish. We've moved our council coverage to the morning slot and it's our most-read section now. | F9: Editor, Calder Valley Voice | H9: 46191 | I9: analytics,audience | J9: human
A10: Newsroom Champions (internal) | B10: Colleagues confident explaining the programme | C10: quote | D10: Policy colleague on the champions session | E10: I used the local newsroom examples in a meeting with a ministry team the following week. Having real numbers made the conversation much easier. | F10: Champion, Government Affairs & Public Policy | H10: 46273 | I10: gapp,champions | J10: human
A11: Newsroom Tools Partnership | B11: Minutes saved per story | C11: quote | D11: Reporter on automated transcription | E11: Transcribing a council meeting used to take me an evening. Now I have a draft in twenty minutes and spend the time chasing the story. | F11: Reporter, Coastal Courier | H11: 46213 | I11: tools,time-saved | J11: human
A12: Newsroom Tools Partnership | B12: Partner satisfaction (NPS) | C12: survey | D12: Q3 user survey (n=146) | E12: NPS rose from 26 to 31. Most common complaint: the analytics tool's setup takes too long without support. | F12: User survey, September | H12: 46270 | I12: survey,nps | J12: human
A13: Local News Audience Study | B13: Citations in policy papers and press | C13: link | D13: Study cited in national press | E13: Coverage of brief 2 (who pays for local news) in a national newspaper's media section. | F13: National press | G13: https://example.org/press/local-news-study | H13: 46254 | I13: press,citation | J13: human
A14: Local News Audience Study | B14: Survey responses collected | C14: survey | D14: Headline finding from brief 2 | E14: 62% of local news readers would pay something for local news, but only 14% currently do. Price sensitivity is highest under 35. | F14: Local News Audience Study, brief 2 | H14: 46233 | I14: survey,revenue | J14: human
A15: Global News Summit 2026 | B15: Partnerships started after events | C15: case-study | D15: Two newsrooms share a data reporter | E15: After meeting at the July roadshow, two county newsrooms now share a data reporter and co-publish investigations. | F15: Programme case study | H15: 46277 | I15: partnerships,events | J15: human
A16: Lunch & Learn series (internal) | B16: Attendees who understand the programme better | C16: quote | D16: Sales colleague after a session | E16: I finally get what the programme does. I've already used the Tyneside membership story with a client. | F16: Attendee, Advertising sales | H16: 46248 | I16: internal,comms | J16: human
A17: Policy Engagement on Local News | B17: Follow-up requests from officials | C17: quote | D17: Adviser in a ministry team | E17: The newsroom case studies were exactly what we needed. Could you send the survey figures by region? | F17: Policy adviser, national government | H17: 46262 | I17: gapp,policy | J17: human
A18: Policy Engagement on Local News | B18: Programme evidence cited in policy documents | C18: link | D18: Consultation response on local media | E18: Our written response to the local media consultation, drawing on the audience study and training results. | F18: GAPP | G18: https://example.org/policy/consultation-response | H18: 46283 | I18: gapp,submission | J18: human

Sheet Spend
A1: Initiative | B1: Date | C1: Amount | D1: Category | E1: Status | F1: Description | G1: Reference | H1: Focus area (calculated)
A2: Newsroom Digital Skills Training | B2: 46109 | C2: 5000 | D2: staff | E2: actual | F2: Programme staff and trainers | G2: PAY-03 | H2: =IFERROR(INDEX(Initiatives!$B$2:$B$500,MATCH(A2,Initiatives!$A$2:$A$500,0)),"")
A3: Newsroom Champions (internal) | B3: 46109 | C3: 1200 | D3: staff | E3: actual | F3: Session facilitation | H3: =IFERROR(INDEX(Initiatives!$B$2:$B$500,MATCH(A3,Initiatives!$A$2:$A$500,0)),"")
A4: Newsroom Digital Skills Training | B4: 46127 | C4: 12000 | D4: vendors | E4: actual | F4: Analytics and CMS toolkit licence (annual) | G4: PO-4102 | H4: =IFERROR(INDEX(Initiatives!$B$2:$B$500,MATCH(A4,Initiatives!$A$2:$A$500,0)),"")
A5: Newsroom Digital Skills Training | B5: 46140 | C5: 5000 | D5: staff | E5: actual | F5: Programme staff and trainers | G5: PAY-04 | H5: =IFERROR(INDEX(Initiatives!$B$2:$B$500,MATCH(A5,Initiatives!$A$2:$A$500,0)),"")
A6: Newsroom Champions (internal) | B6: 46140 | C6: 1200 | D6: staff | E6: actual | F6: Session facilitation | H6: =IFERROR(INDEX(Initiatives!$B$2:$B$500,MATCH(A6,Initiatives!$A$2:$A$500,0)),"")
A7: Newsroom Digital Skills Training | B7: 46140 | C7: 8000 | D7: grants | E7: actual | F7: Newsroom training grants | G7: GR-04 | H7: =IFERROR(INDEX(Initiatives!$B$2:$B$500,MATCH(A7,Initiatives!$A$2:$A$500,0)),"")
A8: Newsroom Champions (internal) | B8: 46142 | C8: 2100 | D8: events | E8: actual | F8: Internal launch town hall | H8: =IFERROR(INDEX(Initiatives!$B$2:$B$500,MATCH(A8,Initiatives!$A$2:$A$500,0)),"")
A9: Newsroom Digital Skills Training | B9: 46170 | C9: 5000 | D9: staff | E9: actual | F9: Programme staff and trainers | G9: PAY-05 | H9: =IFERROR(INDEX(Initiatives!$B$2:$B$500,MATCH(A9,Initiatives!$A$2:$A$500,0)),"")
A10: Newsroom Champions (internal) | B10: 46170 | C10: 1200 | D10: staff | E10: actual | F10: Session facilitation | H10: =IFERROR(INDEX(Initiatives!$B$2:$B$500,MATCH(A10,Initiatives!$A$2:$A$500,0)),"")
A11: Newsroom Digital Skills Training | B11: 46170 | C11: 6800 | D11: grants | E11: actual | F11: Newsroom training grants | G11: GR-05 | H11: =IFERROR(INDEX(Initiatives!$B$2:$B$500,MATCH(A11,Initiatives!$A$2:$A$500,0)),"")
A12: Newsroom Digital Skills Training | B12: 46173 | C12: 800 | D12: marketing | E12: actual | F12: Toolkit launch email series | H12: =IFERROR(INDEX(Initiatives!$B$2:$B$500,MATCH(A12,Initiatives!$A$2:$A$500,0)),"")
A13: Newsroom Digital Skills Training | B13: 46188 | C13: 3000 | D13: travel | E13: actual | F13: Trainer travel, cohorts 1-3 | H13: =IFERROR(INDEX(Initiatives!$B$2:$B$500,MATCH(A13,Initiatives!$A$2:$A$500,0)),"")
A14: Newsroom Digital Skills Training | B14: 46201 | C14: 5000 | D14: staff | E14: actual | F14: Programme staff and trainers | G14: PAY-06 | H14: =IFERROR(INDEX(Initiatives!$B$2:$B$500,MATCH(A14,Initiatives!$A$2:$A$500,0)),"")
A15: Newsroom Champions (internal) | B15: 46201 | C15: 1200 | D15: staff | E15: actual | F15: Session facilitation | H15: =IFERROR(INDEX(Initiatives!$B$2:$B$500,MATCH(A15,Initiatives!$A$2:$A$500,0)),"")
A16: Newsroom Digital Skills Training | B16: 46201 | C16: 9200 | D16: grants | E16: actual | F16: Newsroom training grants | G16: GR-06 | H16: =IFERROR(INDEX(Initiatives!$B$2:$B$500,MATCH(A16,Initiatives!$A$2:$A$500,0)),"")
A17: Newsroom Digital Skills Training | B17: 46203 | C17: 6000 | D17: marketing | E17: actual | F17: Local News Matters YouTube series production | G17: PO-4410 | H17: =IFERROR(INDEX(Initiatives!$B$2:$B$500,MATCH(A17,Initiatives!$A$2:$A$500,0)),"")
A18: Newsroom Champions (internal) | B18: 46203 | C18: 600 | D18: other | E18: actual | F18: Champions certificates and materials | H18: =IFERROR(INDEX(Initiatives!$B$2:$B$500,MATCH(A18,Initiatives!$A$2:$A$500,0)),"")
A19: Newsroom Digital Skills Training | B19: 46231 | C19: 5000 | D19: staff | E19: actual | F19: Programme staff and trainers | G19: PAY-07 | H19: =IFERROR(INDEX(Initiatives!$B$2:$B$500,MATCH(A19,Initiatives!$A$2:$A$500,0)),"")
A20: Newsroom Champions (internal) | B20: 46231 | C20: 1200 | D20: staff | E20: actual | F20: Session facilitation | H20: =IFERROR(INDEX(Initiatives!$B$2:$B$500,MATCH(A20,Initiatives!$A$2:$A$500,0)),"")
A21: Newsroom Digital Skills Training | B21: 46231 | C21: 8000 | D21: grants | E21: actual | F21: Newsroom training grants | G21: GR-07 | H21: =IFERROR(INDEX(Initiatives!$B$2:$B$500,MATCH(A21,Initiatives!$A$2:$A$500,0)),"")
A22: Newsroom Digital Skills Training | B22: 46234 | C22: 4500 | D22: events | E22: actual | F22: Newsroom Futures roadshow: venues and catering (July) | H22: =IFERROR(INDEX(Initiatives!$B$2:$B$500,MATCH(A22,Initiatives!$A$2:$A$500,0)),"")
A23: Newsroom Digital Skills Training | B23: 46262 | C23: 5000 | D23: staff | E23: actual | F23: Programme staff and trainers | G23: PAY-08 | H23: =IFERROR(INDEX(Initiatives!$B$2:$B$500,MATCH(A23,Initiatives!$A$2:$A$500,0)),"")
A24: Newsroom Champions (internal) | B24: 46262 | C24: 1200 | D24: staff | E24: actual | F24: Session facilitation | H24: =IFERROR(INDEX(Initiatives!$B$2:$B$500,MATCH(A24,Initiatives!$A$2:$A$500,0)),"")
A25: Newsroom Digital Skills Training | B25: 46262 | C25: 6800 | D25: grants | E25: actual | F25: Newsroom training grants | G25: GR-08 | H25: =IFERROR(INDEX(Initiatives!$B$2:$B$500,MATCH(A25,Initiatives!$A$2:$A$500,0)),"")
A26: Newsroom Digital Skills Training | B26: 46265 | C26: 4500 | D26: events | E26: actual | F26: Newsroom Futures roadshow: venues and catering (August) | H26: =IFERROR(INDEX(Initiatives!$B$2:$B$500,MATCH(A26,Initiatives!$A$2:$A$500,0)),"")
A27: Newsroom Digital Skills Training | B27: 46293 | C27: 5000 | D27: staff | E27: actual | F27: Programme staff and trainers | G27: PAY-09 | H27: =IFERROR(INDEX(Initiatives!$B$2:$B$500,MATCH(A27,Initiatives!$A$2:$A$500,0)),"")
A28: Newsroom Champions (internal) | B28: 46293 | C28: 1200 | D28: staff | E28: actual | F28: Session facilitation | H28: =IFERROR(INDEX(Initiatives!$B$2:$B$500,MATCH(A28,Initiatives!$A$2:$A$500,0)),"")
A29: Newsroom Digital Skills Training | B29: 46293 | C29: 9200 | D29: grants | E29: actual | F29: Newsroom training grants | G29: GR-09 | H29: =IFERROR(INDEX(Initiatives!$B$2:$B$500,MATCH(A29,Initiatives!$A$2:$A$500,0)),"")
A30: Newsroom Digital Skills Training | B30: 46315 | C30: 7500 | D30: events | E30: committed | F30: Cohort 7 venue booking | G30: PO-5530 | H30: =IFERROR(INDEX(Initiatives!$B$2:$B$500,MATCH(A30,Initiatives!$A$2:$A$500,0)),"")
A31: Newsroom Digital Skills Training | B31: 46327 | C31: 5000 | D31: vendors | E31: committed | F31: Toolkit support contract (Q4) | G31: PO-5541 | H31: =IFERROR(INDEX(Initiatives!$B$2:$B$500,MATCH(A31,Initiatives!$A$2:$A$500,0)),"")
A32: Newsroom Tools Partnership | B32: 46140 | C32: 12000 | D32: vendors | E32: actual | F32: Integration work, phase 1 | H32: =IFERROR(INDEX(Initiatives!$B$2:$B$500,MATCH(A32,Initiatives!$A$2:$A$500,0)),"")
A33: Newsroom Tools Partnership | B33: 46201 | C33: 8000 | D33: vendors | E33: actual | F33: Integration work, phase 2 | H33: =IFERROR(INDEX(Initiatives!$B$2:$B$500,MATCH(A33,Initiatives!$A$2:$A$500,0)),"")
A34: Newsroom Tools Partnership | B34: 46201 | C34: 3000 | D34: events | E34: actual | F34: Tools launch webinars | H34: =IFERROR(INDEX(Initiatives!$B$2:$B$500,MATCH(A34,Initiatives!$A$2:$A$500,0)),"")
A35: Newsroom Tools Partnership | B35: 46341 | C35: 8000 | D35: vendors | E35: committed | F35: Integration work, phase 3 | H35: =IFERROR(INDEX(Initiatives!$B$2:$B$500,MATCH(A35,Initiatives!$A$2:$A$500,0)),"")
A36: Newsroom Tools Partnership | B36: 46109 | C36: 3000 | D36: staff | E36: actual | F36: Partnerships manager (part) | H36: =IFERROR(INDEX(Initiatives!$B$2:$B$500,MATCH(A36,Initiatives!$A$2:$A$500,0)),"")
A37: Newsroom Tools Partnership | B37: 46140 | C37: 3000 | D37: staff | E37: actual | F37: Partnerships manager (part) | H37: =IFERROR(INDEX(Initiatives!$B$2:$B$500,MATCH(A37,Initiatives!$A$2:$A$500,0)),"")
A38: Newsroom Tools Partnership | B38: 46170 | C38: 3000 | D38: staff | E38: actual | F38: Partnerships manager (part) | H38: =IFERROR(INDEX(Initiatives!$B$2:$B$500,MATCH(A38,Initiatives!$A$2:$A$500,0)),"")
A39: Newsroom Tools Partnership | B39: 46201 | C39: 3000 | D39: staff | E39: actual | F39: Partnerships manager (part) | H39: =IFERROR(INDEX(Initiatives!$B$2:$B$500,MATCH(A39,Initiatives!$A$2:$A$500,0)),"")
A40: Newsroom Tools Partnership | B40: 46231 | C40: 3000 | D40: staff | E40: actual | F40: Partnerships manager (part) | H40: =IFERROR(INDEX(Initiatives!$B$2:$B$500,MATCH(A40,Initiatives!$A$2:$A$500,0)),"")
...

Sheet Responsibilities
A1: Title | B1: Description | C1: Type | D1: Team | E1: Owner | F1: Focus area | G1: Initiative | H1: Due date | I1: Repeats | J1: Status | K1: Completed on | L1: Notes
A2: Q2 report to funders | C2: report | D2: programme | E2: Tom Reeves | F2: Trainings | H2: 46218 | I2: quarterly | J2: done | K2: 46217
A3: Impact figures for the corporate annual report | B3: Five headline stats and two case studies, cleared for external use. | C3: report | D3: comms | E3: Priya Shah | F3: Trainings | H3: 46280 | I3: none | J3: open
A4: Renew analytics toolkit vendor contract | B4: Current licence ends in October. Vendor has proposed a 12% increase. | C4: contract | D4: programme | E4: Nadia Hassan | F4: Trainings | G4: Newsroom Digital Skills Training | H4: 46285 | I4: none | J4: in-progress
A5: Sign off champions certification | C5: approval | D5: programme | E5: Tom Reeves | F5: Trainings | G5: Newsroom Champions (internal) | H5: 46291 | I5: none | J5: open
A6: Approve monthly expenses | C6: approval | D6: programme | E6: Nadia Hassan | F6: Trainings | H6: 46295 | I6: monthly | J6: open
A7: Policy briefing: local news and democracy | B7: Briefing for the ministry roundtable, using headline figures and newsroom case studies. | C7: report | D7: gapp | E7: Daniel Mensah | F7: Trainings | H7: 46297 | I7: none | J7: in-progress
A8: Q4 recruitment plan for training cohorts | C8: admin | D8: marketing | E8: Sofia Lindqvist | F8: Trainings | G8: Newsroom Digital Skills Training | H8: 46305 | I8: none | J8: open
A9: Q3 report to funders | B9: Progress against targets, spend and case studies. Use the Q3 snapshot. | C9: report | D9: programme | E9: Tom Reeves | F9: Trainings | H9: 46310 | I9: quarterly | J9: open
A10: Grant agreements for cohort 4 newsrooms | C10: contract | D10: programme | E10: Tom Reeves | F10: Trainings | G10: Newsroom Digital Skills Training | H10: 46326 | I10: none | J10: open
A11: Safeguarding and data protection review | C11: compliance | D11: programme | E11: Nadia Hassan | F11: Trainings | H11: 46356 | I11: annually | J11: open
A12: Renew partner tool agreements for 2027 | B12: Three partner agreements end in December. | C12: contract | D12: programme | E12: Tom Reeves | F12: Product & Technology Partnerships | G12: Newsroom Tools Partnership | H12: 46325 | I12: none | J12: open
A13: Monthly partner performance review | C13: report | D13: programme | E13: Tom Reeves | F13: Product & Technology Partnerships | G13: Newsroom Tools Partnership | H13: 46290 | I13: monthly | J13: open
A14: Quarterly insights digest for product leadership | C14: report | D14: programme | E14: Tom Reeves | F14: Product & Technology Partnerships | G14: Product Feedback Loop (internal) | H14: 46284 | I14: quarterly | J14: open
A15: Publish brief 4: young audiences | C15: report | D15: programme | E15: Tom Reeves | F15: Research & Insights | G15: Local News Audience Study | H15: 46315 | I15: none | J15: open
A16: Press launch plan for the full report | C16: admin | D16: comms | E16: Priya Shah | F16: Research & Insights | G16: Local News Audience Study | H16: 46301 | I16: none | J16: open
A17: Confirm summit venue contract | C17: contract | D17: programme | E17: Nadia Hassan | F17: Events & Convenings | G17: Global News Summit 2026 | H17: 46295 | I17: none | J17: in-progress
A18: Summit registration campaign, phase 2 | C18: admin | D18: marketing | E18: Sofia Lindqvist | F18: Events & Convenings | G18: Global News Summit 2026 | H18: 46296 | I18: none | J18: open
A19: Summit accessibility and safeguarding plan | C19: compliance | D19: programme | E19: Nadia Hassan | F19: Events & Convenings | G19: Global News Summit 2026 | H19: 46310 | I19: none | J19: open
A20: Book Lunch & Learn speakers for Q4 | C20: admin | D20: comms | E20: Priya Shah | F20: Events & Convenings | G20: Lunch & Learn series (internal) | H20: 46283 | I20: none | J20: open
A21: Response to the local media consultation | C21: report | D21: gapp | E21: Daniel Mensah | F21: Policy & Public Affairs | G21: Policy Engagement on Local News | H21: 46277 | I21: none | J21: done | K21: 46276
A22: Prepare evidence pack for the parliamentary committee | C22: report | D22: gapp | E22: Daniel Mensah | F22: Policy & Public Affairs | G22: Policy Engagement on Local News | H22: 46304 | I22: none | J22: in-progress
A23: Quarterly policy horizon scan | C23: report | D23: gapp | E23: Daniel Mensah | F23: Policy & Public Affairs | G23: Policy Engagement on Local News | H23: 46296 | I23: quarterly | J23: open

Sheet Risks
A1: Title | B1: Description | C1: Likelihood (1-5) | D1: Impact (1-5) | E1: Status | F1: Owner | G1: Focus area | H1: Initiative | I1: Next review | J1: Mitigation | K1: Score (calculated) | L1: Rating (calculated)
A2: Digital audience growth misses target | B2: Audience growth is off track and its leading indicator (weekly analytics use) is behind. | C2: 4 | D2: 4 | E2: open | F2: Tom Reeves | G2: Trainings | H2: Newsroom Digital Skills Training | I2: 46296 | J2: One-to-one analytics coaching for the 18 newsrooms not yet using the dashboard weekly. | K2: =IF(AND(ISNUMBER(C2),ISNUMBER(D2)),C2*D2,"") | L2: =IF(K2="","",IF(K2>=15,"High",IF(K2>=8,"Medium","Low")))
A3: Partner newsrooms drop out before cohort 4 | C3: 3 | D3: 4 | E3: open | F3: Tom Reeves | G3: Trainings | H3: Newsroom Digital Skills Training | I3: 46310 | J3: Monthly check-ins; grant tranches tied to attendance; peer mentoring pairs. | K3: =IF(AND(ISNUMBER(C3),ISNUMBER(D3)),C3*D3,"") | L3: =IF(K3="","",IF(K3>=15,"High",IF(K3>=8,"Medium","Low")))
A4: Toolkit vendor price rise at renewal | C4: 4 | D4: 3 | E4: open | F4: Nadia Hassan | G4: Trainings | H4: Newsroom Digital Skills Training | I4: 46280 | J4: Negotiate a two-year rate; price an alternative supplier by end of September. | K4: =IF(AND(ISNUMBER(C4),ISNUMBER(D4)),C4*D4,"") | L4: =IF(K4="","",IF(K4>=15,"High",IF(K4>=8,"Medium","Low")))
A5: Data protection issue with shared newsroom analytics | C5: 2 | D5: 5 | E5: mitigating | F5: Nadia Hassan | G5: Trainings | I5: 46356 | J5: Data processing agreements signed with all newsrooms; access reviewed quarterly. | K5: =IF(AND(ISNUMBER(C5),ISNUMBER(D5)),C5*D5,"") | L5: =IF(K5="","",IF(K5>=15,"High",IF(K5>=8,"Medium","Low")))
A6: Internal budget underspent and returned at year end | C6: 3 | D6: 2 | E6: open | F6: Nadia Hassan | G6: Trainings | H6: Newsroom Champions (internal) | I6: 46326 | J6: Extend champions sessions to regional offices from October. | K6: =IF(AND(ISNUMBER(C6),ISNUMBER(D6)),C6*D6,"") | L6: =IF(K6="","",IF(K6>=15,"High",IF(K6>=8,"Medium","Low")))
A7: Ministry roundtable postponed | C7: 2 | D7: 3 | E7: open | F7: Daniel Mensah | G7: Trainings | I7: 46296 | J7: Prepare a written briefing that can be sent if the meeting slips. | K7: =IF(AND(ISNUMBER(C7),ISNUMBER(D7)),C7*D7,"") | L7: =IF(K7="","",IF(K7>=15,"High",IF(K7>=8,"Medium","Low")))
A8: Partner changes tool pricing for newsrooms | C8: 3 | D8: 4 | E8: open | F8: Tom Reeves | G8: Product & Technology Partnerships | H8: Newsroom Tools Partnership | I8: 46310 | J8: Agree fixed pricing to the end of 2027 in the renewal. | K8: =IF(AND(ISNUMBER(C8),ISNUMBER(D8)),C8*D8,"") | L8: =IF(K8="","",IF(K8>=15,"High",IF(K8>=8,"Medium","Low")))
A9: Low weekly use means partners lose interest | C9: 3 | D9: 3 | E9: open | F9: Tom Reeves | G9: Product & Technology Partnerships | H9: Newsroom Tools Partnership | I9: 46296 | J9: Tool clinics for newsrooms below weekly use; share usage data with partners monthly. | K9: =IF(AND(ISNUMBER(C9),ISNUMBER(D9)),C9*D9,"") | L9: =IF(K9="","",IF(K9>=15,"High",IF(K9>=8,"Medium","Low")))
A10: Product teams deprioritise newsroom requests | C10: 3 | D10: 3 | E10: open | F10: Tom Reeves | G10: Product & Technology Partnerships | H10: Product Feedback Loop (internal) | I10: 46326 | J10: Agree two newsroom features per quarter with product leadership. | K10: =IF(AND(ISNUMBER(C10),ISNUMBER(D10)),C10*D10,"") | L10: =IF(K10="","",IF(K10>=15,"High",IF(K10>=8,"Medium","Low")))
A11: Report launch misses the policy window | C11: 2 | D11: 4 | E11: open | F11: Tom Reeves | G11: Research & Insights | H11: Local News Audience Study | I11: 46305 | J11: Publish briefs early and share embargoed findings with GAPP. | K11: =IF(AND(ISNUMBER(C11),ISNUMBER(D11)),C11*D11,"") | L11: =IF(K11="","",IF(K11>=15,"High",IF(K11>=8,"Medium","Low")))
A12: Summit registrations fall short of 800 | C12: 3 | D12: 4 | E12: open | F12: Sofia Lindqvist | G12: Events & Convenings | H12: Global News Summit 2026 | I12: 46296 | J12: Phase 2 campaign through partner newsletters; group discounts for newsrooms. | K12: =IF(AND(ISNUMBER(C12),ISNUMBER(D12)),C12*D12,"") | L12: =IF(K12="","",IF(K12>=15,"High",IF(K12>=8,"Medium","Low")))
A13: Sponsor shortfall leaves a budget gap | C13: 4 | D13: 3 | E13: open | F13: Nadia Hassan | G13: Events & Convenings | H13: Global News Summit 2026 | I13: 46285 | J13: Scale the online track; approach two additional foundations. | K13: =IF(AND(ISNUMBER(C13),ISNUMBER(D13)),C13*D13,"") | L13: =IF(K13="","",IF(K13>=15,"High",IF(K13>=8,"Medium","Low")))
A14: Election period limits access to officials | C14: 3 | D14: 3 | E14: open | F14: Daniel Mensah | G14: Policy & Public Affairs | H14: Policy Engagement on Local News | I14: 46327 | J14: Front-load briefings before the pre-election period; focus on officials, not ministers. | K14: =IF(AND(ISNUMBER(C14),ISNUMBER(D14)),C14*D14,"") | L14: =IF(K14="","",IF(K14>=15,"High",IF(K14>=8,"Medium","Low")))
K15: =IF(AND(ISNUMBER(C15),ISNUMBER(D15)),C15*D15,"") | L15: =IF(K15="","",IF(K15>=15,"High",IF(K15>=8,"Medium","Low")))
K16: =IF(AND(ISNUMBER(C16),ISNUMBER(D16)),C16*D16,"") | L16: =IF(K16="","",IF(K16>=15,"High",IF(K16>=8,"Medium","Low")))
K17: =IF(AND(ISNUMBER(C17),ISNUMBER(D17)),C17*D17,"") | L17: =IF(K17="","",IF(K17>=15,"High",IF(K17>=8,"Medium","Low")))
K18: =IF(AND(ISNUMBER(C18),ISNUMBER(D18)),C18*D18,"") | L18: =IF(K18="","",IF(K18>=15,"High",IF(K18>=8,"Medium","Low")))
K19: =IF(AND(ISNUMBER(C19),ISNUMBER(D19)),C19*D19,"") | L19: =IF(K19="","",IF(K19>=15,"High",IF(K19>=8,"Medium","Low")))
K20: =IF(AND(ISNUMBER(C20),ISNUMBER(D20)),C20*D20,"") | L20: =IF(K20="","",IF(K20>=15,"High",IF(K20>=8,"Medium","Low")))
